Workbook
Name ½_L4: Sheet2!$B$7
Name d: Sheet2!$B$4
Name d_2: Sheet2!$F$4
Name L: Sheet1!$C$3
Name L_4: Sheet2!$B$6
Name L_4_2: Sheet2!$F$6
Name Rmin: Sheet1!$C$4
Name W: Sheet1!$C$2
Name W_2: Sheet2!$F$2

Sheet Sheet1
A2: Track Width | B2: W | C2: ='Input Parameters'!B1 -> 160 | D2: mm | F2: =W/L -> 0.72727273 | H2: Rule of Thumb
A3: Wheelbase | B3: L | C3: ='Input Parameters'!B2 -> 220 | D3: mm | H3: beta | I3: =DEGREES(ATAN((W/2)/L)) -> 19.983107
A4: Min Radius | B4: Rmin | C4: ='Input Parameters'!B3 -> 400 | D4: mm | N4: ="W = "&TEXT(W,"0.0")&" mm"&N5&"L = "&TEXT(L,"0.0")&" mm"&N5&"W/L = "&TEXT(W/L,"0.0000")&N5&"Rmin = "&TEXT(Rmin,"0.0")&" mm"&N5&"W/d ≈ "&TEXT(Sheet2!B3,"0.000")&N5&"d = "&TEXT(Sheet2!B4,"0")&N5&"β = "&TEXT(Sheet2!B5,"0.0")&"°" -> W = 160.0 mm L = 220.0 mm W/L = 0.7273 Rmin = 400.0 mm W/d ≈ 4.000 d = 40 β = 26.0°
E5: Ackermann
A6: Turn Radius | B6: Inner Angle | C6: Outer Angle | E6: =C6&" vs "&B6&" for W/L = "&TEXT(F2,"0.000") -> Outer Angle vs Inner Angle for W/L = 0.727
A7: rt (mm) | B7: di (°) | C7: do (°)
A8: =Rmin -> 400 | B8: =DEGREES(ATAN(L/($A8-W/2))) -> 34.508523 | C8: =DEGREES(ATAN(L/($A8+W/2))) -> 24.623565
A9: =A8+10 -> 410 | B9: =DEGREES(ATAN(L/($A9-W/2))) -> 33.690068 | C9: =DEGREES(ATAN(L/($A9+W/2))) -> 24.179107
A10: =A9+10 -> 420 | B10: =DEGREES(ATAN(L/($A10-W/2))) -> 32.905243 | C10: =DEGREES(ATAN(L/($A10+W/2))) -> 23.749494
A11: =A10+10 -> 430 | B11: =DEGREES(ATAN(L/($A11-W/2))) -> 32.152295 | C11: =DEGREES(ATAN(L/($A11+W/2))) -> 23.334041
A12: =A11+10 -> 440 | B12: =DEGREES(ATAN(L/($A12-W/2))) -> 31.429566 | C12: =DEGREES(ATAN(L/($A12+W/2))) -> 22.9321
A13: =A12+10 -> 450 | B13: =DEGREES(ATAN(L/($A13-W/2))) -> 30.735488 | C13: =DEGREES(ATAN(L/($A13+W/2))) -> 22.543061
A14: =A13+10 -> 460 | B14: =DEGREES(ATAN(L/($A14-W/2))) -> 30.068583 | C14: =DEGREES(ATAN(L/($A14+W/2))) -> 22.166346
A15: =A14+10 -> 470 | B15: =DEGREES(ATAN(L/($A15-W/2))) -> 29.427456 | C15: =DEGREES(ATAN(L/($A15+W/2))) -> 21.801409
A16: =A15+10 -> 480 | B16: =DEGREES(ATAN(L/($A16-W/2))) -> 28.810794 | C16: =DEGREES(ATAN(L/($A16+W/2))) -> 21.447736
A17: =A16+10 -> 490 | B17: =DEGREES(ATAN(L/($A17-W/2))) -> 28.217356 | C17: =DEGREES(ATAN(L/($A17+W/2))) -> 21.104839
A18: =A17+10 -> 500 | B18: =DEGREES(ATAN(L/($A18-W/2))) -> 27.645975 | C18: =DEGREES(ATAN(L/($A18+W/2))) -> 20.772255
A19: =A18+10 -> 510 | B19: =DEGREES(ATAN(L/($A19-W/2))) -> 27.095552 | C19: =DEGREES(ATAN(L/($A19+W/2))) -> 20.449548
A20: =A19+10 -> 520 | B20: =DEGREES(ATAN(L/($A20-W/2))) -> 26.565051 | C20: =DEGREES(ATAN(L/($A20+W/2))) -> 20.136303
... A37: =A36+10 -> 690 | B37: =DEGREES(ATAN(L/($A37-W/2))) -> 19.83213 | C37: =DEGREES(ATAN(L/($A37+W/2))) -> 15.945396
A38: =A37+20 -> 710 | B38: =DEGREES(ATAN(L/($A38-W/2))) -> 19.249526 | C38: =DEGREES(ATAN(L/($A38+W/2))) -> 15.56151
A39: =A38+20 -> 730 | B39: =DEGREES(ATAN(L/($A39-W/2))) -> 18.698983 | C39: =DEGREES(ATAN(L/($A39+W/2))) -> 15.195249
A40: =A39+20 -> 750 | B40: =DEGREES(ATAN(L/($A40-W/2))) -> 18.178019 | C40: =DEGREES(ATAN(L/($A40+W/2))) -> 14.845452
A41: =A40+20 -> 770 | B41: =DEGREES(ATAN(L/($A41-W/2))) -> 17.684392 | C41: =DEGREES(ATAN(L/($A41+W/2))) -> 14.51106
A42: =A41+20 -> 790 | B42: =DEGREES(ATAN(L/($A42-W/2))) -> 17.216074 | C42: =DEGREES(ATAN(L/($A42+W/2))) -> 14.191097
A43: =A42+20 -> 810 | B43: =DEGREES(ATAN(L/($A43-W/2))) -> 16.771224 | C43: =DEGREES(ATAN(L/($A43+W/2))) -> 13.884668
A44: =A43+20 -> 830 | B44: =DEGREES(ATAN(L/($A44-W/2))) -> 16.348172 | C44: =DEGREES(ATAN(L/($A44+W/2))) -> 13.590948
A45: =A44+20 -> 850 | B45: =DEGREES(ATAN(L/($A45-W/2))) -> 15.945396 | C45: =DEGREES(ATAN(L/($A45+W/2))) -> 13.309179
A46: =A45+20 -> 870 | B46: =DEGREES(ATAN(L/($A46-W/2))) -> 15.56151 | C46: =DEGREES(ATAN(L/($A46+W/2))) -> 13.038657
A47: =A46+20 -> 890 | B47: =DEGREES(ATAN(L/($A47-W/2))) -> 15.195249 | C47: =DEGREES(ATAN(L/($A47+W/2))) -> 12.778733
A48: =A47+20 -> 910 | B48: =DEGREES(ATAN(L/($A48-W/2))) -> 14.845452 | C48: =DEGREES(ATAN(L/($A48+W/2))) -> 12.528808
A49: =A48+20 -> 930 | B49: =DEGREES(ATAN(L/($A49-W/2))) -> 14.51106 | C49: =DEGREES(ATAN(L/($A49+W/2))) -> 12.288323
... A57: =A56+20 -> 1090 | B57: =DEGREES(ATAN(L/($A57-W/2))) -> 12.288323 | C57: =DEGREES(ATAN(L/($A57+W/2))) -> 10.64922
A58: =A57+40 -> 1130 | B58: =DEGREES(ATAN(L/($A58-W/2))) -> 11.833645 | C58: =DEGREES(ATAN(L/($A58+W/2))) -> 10.304846
A59: =A58+40 -> 1170 | B59: =DEGREES(ATAN(L/($A59-W/2))) -> 11.410983 | C59: =DEGREES(ATAN(L/($A59+W/2))) -> 9.9818293
A60: =A59+40 -> 1210 | B60: =DEGREES(ATAN(L/($A60-W/2))) -> 11.017112 | C60: =DEGREES(ATAN(L/($A60+W/2))) -> 9.6782601
A61: =A60+40 -> 1250 | B61: =DEGREES(ATAN(L/($A61-W/2))) -> 10.64922 | C61: =DEGREES(ATAN(L/($A61+W/2))) -> 9.3924493
A62: =A61+40 -> 1290 | B62: =DEGREES(ATAN(L/($A62-W/2))) -> 10.304846 | C62: =DEGREES(ATAN(L/($A62+W/2))) -> 9.1228962
A63: =A62+40 -> 1330 | B63: =DEGREES(ATAN(L/($A63-W/2))) -> 9.9818293 | C63: =DEGREES(ATAN(L/($A63+W/2))) -> 8.8682628
A64: =A63+40 -> 1370 | B64: =DEGREES(ATAN(L/($A64-W/2))) -> 9.6782601 | C64: =DEGREES(ATAN(L/($A64+W/2))) -> 8.6273531
...

Sheet Sheet2
A1: Trapezoidal Steering Angles
A2: W | B2: =W -> 160 | C2: mm | E2: W^2 | F2: =B2*B2 -> 25600 | L2: =RADIANS(Sheet1!B8)/40 -> 0.015057184 | AJ2: 1
A3: W/d | B3: =IF(ISNUMBER('Input Parameters'!B5),'Input Parameters'!B1/'Input Parameters'!B5,'Input Parameters'!B4) -> 4 | J3: Four bar Linkage | L3: theta_2 | M3: BD | N3: BD^2 | O3: gamma | P3: alpha | Q3: delta | R3: theta_4 | S3: theta_5 | T3: theta_3 | W3: delta_i | X3: delta_o | Y3: delta_i | Z3: delta_o | AE3: slcx | AF3: slcy | AG3: Lateral | AH3: Longitudinal
A4: d | B4: =ROUND(B2/B3,0) -> 40 | C4: mm | E4: d^2 | F4: =B4*B4 -> 1600 | J4: =d*COS(RADIANS(B5)) -> 35.951762 | K4: 1 | L4: =RADIANS(90-B5) -> 1.1170107 | M4: =SQRT(d_2+W_2-2*d*W*COS(L4)) -> 146.93144 | N4: =M4*M4 -> 21588.849 | O4: =ACOS((N4-d_2-L_4_2)/(-2*d*L_4)) -> 2.0245819 | P4: =ACOS((d_2-N4-W_2)/(-2*M4*W)) -> 0.24719369 | Q4: =ACOS((L_4_2-N4-d_2)/(-2*d*M4)) -> 0.86981703 | R4: =PI()-Q4-P4 -> 2.0245819 | S4: =2*PI()-P4-O4-L4-Q4 -> 2.0245819 | T4: =S4+L4-PI() -> 0 | U4: =d*COS(L4)+½_L4*COS(T4) -> 80 | V4: =d*SIN(L4)+½_L4*SIN(T4) -> 35.951762 | W4: =$L$4-L4 -> 0 | X4: =RADIANS(90+$B$5)-R4 -> 0 | Y4: =DEGREES(W4) -> 0 | Z4: =DEGREES(X4) -> 0 | AA4: =d*COS(L4) -> 17.534846 | AB4: =d*SIN(L4) -> 35.951762 | AC4: =W+d*COS(R4) -> 142.46515 | AD4: =d*SIN(R4) -> 35.951762 | AE4: =(AA4+AC4)/2 -> 80 | AF4: =(AB4+AD4)/2 -> 35.951762 | AG4: =AE4-AE$4 -> 0 | AH4: =ABS(AF4-AF$4) -> 0 | AJ4: 0 | AK4: 0
A5: b | B5: ='Input Parameters'!B6 -> 26 | C5: ° | J5: =J4/B2 -> 0.22469851 | K5: 2 | L5: =L4-$L$2 -> 1.1019535 | M5: =SQRT(d_2+W_2-2*d*W*COS(L5)) -> 146.34297 | N5: =M5*M5 -> 21416.266 | O5: =ACOS((N5-d_2-L_4_2)/(-2*d*L_4)) -> 2.0054575 | P5: =ACOS((d_2-N5-W_2)/(-2*M5*W)) -> 0.24631919 | Q5: =ACOS((L_4_2-N5-d_2)/(-2*d*M5)) -> 0.88560839 | R5: =PI()-Q5-P5 -> 2.0096651 | S5: =2*PI()-P5-O5-L5-Q5 -> 2.0438466 | T5: =S5+L5-PI() -> 0.0042075274 | U5: =d*COS(L5)+½_L4*COS(T5) -> 80.538771 | V5: =d*SIN(L5)+½_L4*SIN(T5) -> 35.946494 | W5: =$L$4-L5 -> 0.015057184 | X5: =RADIANS(90+$B$5)-R5 -> 0.014916859 | Y5: =DEGREES(W5) -> 0.86271307 | Z5: =DEGREES(X5) -> 0.85467304 | AA5: =d*COS(L5) -> 18.07417 | AB5: =d*SIN(L5) -> 35.683671 | AC5: =W+d*COS(R5) -> 143.00337 | AD5: =d*SIN(R5) -> 36.209317 | AE5: =(AA5+AC5)/2 -> 80.538771 | AF5: =(AB5+AD5)/2 -> 35.946494 | AG5: =AE5-AE$4 -> 0.53877121 | AH5: =ABS(AF5-AF$4) -> 0.0052677406 | AJ5: {=d*COS(INDEX($L$4:$L$44,$AJ$2))} -> 17.534846 | AK5: {=d*SIN(INDEX($L$4:$L$44,$AJ$2))} -> 35.951762
A6: L4 | B6: =B2-2*B4*SIN(RADIANS(B5)) -> 124.93031 | C6: mm | E6: L4^2 | F6: =B6*B6 -> 15607.582 | I6: =4.7/14.87 -> 0.31607263 | K6: 3 | L6: =L5-$L$2 -> 1.0868964 | M6: =SQRT(d_2+W_2-2*d*W*COS(L6)) -> 145.75662 | N6: =M6*M6 -> 21244.993 | O6: =ACOS((N6-d_2-L_4_2)/(-2*d*L_4)) -> 1.9866449 | P6: =ACOS((d_2-N6-W_2)/(-2*M6*W)) -> 0.24537695 | Q6: =ACOS((L_4_2-N6-d_2)/(-2*d*M6)) -> 0.90119172 | R6: =PI()-Q6-P6 -> 1.995024 | S6: =2*PI()-P6-O6-L6-Q6 -> 2.0630754 | T6: =S6+L6-PI() -> 0.0083790608 | U6: =d*COS(L6)+½_L4*COS(T6) -> 81.072358 | V6: =d*SIN(L6)+½_L4*SIN(T6) -> 35.930883 | W6: =$L$4-L6 -> 0.030114367 | X6: =RADIANS(90+$B$5)-R6 -> 0.029557952 | Y6: =DEGREES(W6) -> 1.7254261 | Z6: =DEGREES(X6) -> 1.6935459 | AA6: =d*COS(L6) -> 18.609396 | AB6: =d*SIN(L6) -> 35.40749 | AC6: =W+d*COS(R6) -> 143.53532 | AD6: =d*SIN(R6) -> 36.454277 | AE6: =(AA6+AC6)/2 -> 81.072358 | AF6: =(AB6+AD6)/2 -> 35.930883 | AG6: =AE6-AE$4 -> 1.0723578 | AH6: =ABS(AF6-AF$4) -> 0.02087843 | AJ6: {=W+d*COS(INDEX($R$4:$R$44,$AJ$2))} -> 142.46515 | AK6: {=d*SIN(INDEX($R$4:$R$44,$AJ$2))} -> 35.951762
A7: ½ L4 = | B7: =B6/2 -> 62.465154 | C7: mm | K7: 4 | L7: =L6-$L$2 -> 1.0718392 | M7: =SQRT(d_2+W_2-2*d*W*COS(L7)) -> 145.17256 | N7: =M7*M7 -> 21075.071 | O7: =ACOS((N7-d_2-L_4_2)/(-2*d*L_4)) -> 1.9681338 | P7: =ACOS((d_2-N7-W_2)/(-2*M7*W)) -> 0.24436642 | Q7: =ACOS((L_4_2-N7-d_2)/(-2*d*M7)) -> 0.9165743 | R7: =PI()-Q7-P7 -> 1.9806519 | S7: =2*PI()-P7-O7-L7-Q7 -> 2.0822716 | T7: =S7+L7-PI() -> 0.012518127 | U7: =d*COS(L7)+½_L4*COS(T7) -> 81.600664 | V7: =d*SIN(L7)+½_L4*SIN(T7) -> 35.905208 | W7: =$L$4-L7 -> 0.045171551 | X7: =RADIANS(90+$B$5)-R7 -> 0.043929989 | Y7: =DEGREES(W7) -> 2.5881392 | Z7: =DEGREES(X7) -> 2.517003 | AA7: =d*COS(L7) -> 19.140404 | AB7: =d*SIN(L7) -> 35.123282 | AC7: =W+d*COS(R7) -> 144.06092 | AD7: =d*SIN(R7) -> 36.687135 | AE7: =(AA7+AC7)/2 -> 81.600664 | AF7: =(AB7+AD7)/2 -> 35.905208 | AG7: =AE7-AE$4 -> 1.6006638 | AH7: =ABS(AF7-AF$4) -> 0.046553523 | AJ7: =W -> 160 | AK7: 0
A8: Steering Movement (mm) | K8: 5 | L8: =L7-$L$2 -> 1.056782 | M8: =SQRT(d_2+W_2-2*d*W*COS(L8)) -> 144.59093 | N8: =M8*M8 -> 20906.537 | O8: =ACOS((N8-d_2-L_4_2)/(-2*d*L_4)) -> 1.949915 | P8: =ACOS((d_2-N8-W_2)/(-2*M8*W)) -> 0.24328704 | Q8: =ACOS((L_4_2-N8-d_2)/(-2*d*M8)) -> 0.93176261 | R8: =PI()-Q8-P8 -> 1.966543 | S8: =2*PI()-P8-O8-L8-Q8 -> 2.1014387 | T8: =S8+L8-PI() -> 0.016628023 | U8: =d*COS(L8)+½_L4*COS(T8) -> 82.123591 | V8: =d*SIN(L8)+½_L4*SIN(T8) -> 35.869735 | W8: =$L$4-L8 -> 0.060228735 | X8: =RADIANS(90+$B$5)-R8 -> 0.058038927 | Y8: =DEGREES(W8) -> 3.4508523 | Z8: =DEGREES(X8) -> 3.3253856 | AA8: =d*COS(L8) -> 19.667072 | AB8: =d*SIN(L8) -> 34.831111 | AC8: =W+d*COS(R8) -> 144.58011 | AD8: =d*SIN(R8) -> 36.908359 | AE8: =(AA8+AC8)/2 -> 82.123591 | AF8: =(AB8+AD8)/2 -> 35.869735 | AG8: =AE8-AE$4 -> 2.1235907 | AH8: =ABS(AF8-AF$4) -> 0.082026842
A9: Lateral | B9: Longitudinal | K9: 6 | L9: =L8-$L$2 -> 1.0417248 | M9: =SQRT(d_2+W_2-2*d*W*COS(L9)) -> 144.01191 | N9: =M9*M9 -> 20739.43 | O9: =ACOS((N9-d_2-L_4_2)/(-2*d*L_4)) -> 1.9319801 | P9: =ACOS((d_2-N9-W_2)/(-2*M9*W)) -> 0.24213828 | Q9: =ACOS((L_4_2-N9-d_2)/(-2*d*M9)) -> 0.94676247 | R9: =PI()-Q9-P9 -> 1.9526919 | S9: =2*PI()-P9-O9-L9-Q9 -> 2.1205797 | T9: =S9+L9-PI() -> 0.02071184 | U9: =d*COS(L9)+½_L4*COS(T9) -> 82.641038 | V9: =d*SIN(L9)+½_L4*SIN(T9) -> 35.824719 | W9: =$L$4-L9 -> 0.075285918 | X9: =RADIANS(90+$B$5)-R9 -> 0.071890036 | Y9: =DEGREES(W9) -> 4.3135654 | Z9: =DEGREES(X9) -> 4.1189957 | AA9: =d*COS(L9) -> 20.189281 | AB9: =d*SIN(L9) -> 34.531043 | AC9: =W+d*COS(R9) -> 145.09279 | AD9: =d*SIN(R9) -> 37.118394 | AE9: =(AA9+AC9)/2 -> 82.641038 | AF9: =(AB9+AD9)/2 -> 35.824719 | AG9: =AE9-AE$4 -> 2.6410376 | AH9: =ABS(AF9-AF$4) -> 0.12704312
A10: 0 | B10: {=IF(F10<40,INDEX($AH$4:$AH$44,F10)+(A10-INDEX($AG$4:$AG44,F10))*(INDEX($AH$4:$AH$44,F10+1)-INDEX($AH$4:$AH$44,F10))/(INDEX($AG$4:$AG44,F10+1)-INDEX($AG$4:$AG44,F10)),"")} -> 0 | F10: =_xlfn.XMATCH(A10,$AG$4:$AG$44,-1) -> 1 | K10: 7 | L10: =L9-$L$2 -> 1.0266676 | M10: =SQRT(d_2+W_2-2*d*W*COS(L10)) -> 143.43566 | N10: =M10*M10 -> 20573.788 | O10: =ACOS((N10-d_2-L_4_2)/(-2*d*L_4)) -> 1.9143215 | P10: =ACOS((d_2-N10-W_2)/(-2*M10*W)) -> 0.24091964 | Q10: =ACOS((L_4_2-N10-d_2)/(-2*d*M10)) -> 0.96157905 | R10: =PI()-Q10-P10 -> 1.939094 | S10: =2*PI()-P10-O10-L10-Q10 -> 2.1396975 | T10: =S10+L10-PI() -> 0.024772483 | U10: =d*COS(L10)+½_L4*COS(T10) -> 83.152902 | V10: =d*SIN(L10)+½_L4*SIN(T10) -> 35.770405 | W10: =$L$4-L10 -> 0.090343102 | X10: =RADIANS(90+$B$5)-R10 -> 0.085487967 | Y10: =DEGREES(W10) -> 5.1762784 | Z10: =DEGREES(X10) -> 4.8980997 | AA10: =d*COS(L10) -> 20.706913 | AB10: =d*SIN(L10) -> 34.223146 | AC10: =W+d*COS(R10) -> 145.59889 | AD10: =d*SIN(R10) -> 37.317664 | AE10: =(AA10+AC10)/2 -> 83.152902 | AF10: =(AB10+AD10)/2 -> 35.770405 | AG10: =AE10-AE$4 -> 3.1529015 | AH10: =ABS(AF10-AF$4) -> 0.18135676 | AJ10: 41
A11: =A10+1 -> 1 | B11: {=IF(F11<40,INDEX($AH$4:$AH$44,F11)+(A11-INDEX($AG$4:$AG45,F11))*(INDEX($AH$4:$AH$44,F11+1)-INDEX($AH$4:$AH$44,F11))/(INDEX($AG$4:$AG45,F11+1)-INDEX($AG$4:$AG45,F11)),"")} -> 0.018761519 | F11: =_xlfn.XMATCH(A11,$AG$4:$AG$44,-1) -> 2 | K11: 8 | L11: =L10-$L$2 -> 1.0116104 | M11: =SQRT(d_2+W_2-2*d*W*COS(L11)) -> 142.86234 | N11: =M11*M11 -> 20409.648 | O11: =ACOS((N11-d_2-L_4_2)/(-2*d*L_4)) -> 1.8969324 | P11: =ACOS((d_2-N11-W_2)/(-2*M11*W)) -> 0.23963061 | Q11: =ACOS((L_4_2-N11-d_2)/(-2*d*M11)) -> 0.97621692 | R11: =PI()-Q11-P11 -> 1.9257451 | S11: =2*PI()-P11-O11-L11-Q11 -> 2.1587949 | T11: =S11+L11-PI() -> 0.028812691 | U11: =d*COS(L11)+½_L4*COS(T11) -> 83.659078 | V11: =d*SIN(L11)+½_L4*SIN(T11) -> 35.707031 | W11: =$L$4-L11 -> 0.10540029 | X11: =RADIANS(90+$B$5)-R11 -> 0.098836804 | Y11: =DEGREES(W11) -> 6.0389915 | Z11: =DEGREES(X11) -> 5.6629317 | AA11: =d*COS(L11) -> 21.219851 | AB11: =d*SIN(L11) -> 33.907491 | AC11: =W+d*COS(R11) -> 146.09831 | AD11: =d*SIN(R11) -> 37.506571 | AE11: =(AA11+AC11)/2 -> 83.659078 | AF11: =(AB11+AD11)/2 -> 35.707031 | AG11: =AE11-AE$4 -> 3.6590781 | AH11: =ABS(AF11-AF$4) -> 0.24473071 | AJ11: 0 | AK11: 0
A12: =A11+1 -> 2 | B12: {=IF(F12<40,INDEX($AH$4:$AH$44,F12)+(A12-INDEX($AG$4:$AG46,F12))*(INDEX($AH$4:$AH$44,F12+1)-INDEX($AH$4:$AH$44,F12))/(INDEX($AG$4:$AG46,F12+1)-INDEX($AG$4:$AG46,F12)),"")} -> 0.073642932 | F12: =_xlfn.XMATCH(A12,$AG$4:$AG$44,-1) -> 4 | K12: 9 | L12: =L11-$L$2 -> 0.99655325 | M12: =SQRT(d_2+W_2-2*d*W*COS(L12)) -> 142.29212 | N12: =M12*M12 -> 20247.047 | O12: =ACOS((N12-d_2-L_4_2)/(-2*d*L_4)) -> 1.8798068 | P12: =ACOS((d_2-N12-W_2)/(-2*M12*W)) -> 0.23827071 | Q12: =ACOS((L_4_2-N12-d_2)/(-2*d*M12)) -> 0.99068013 | R12: =PI()-Q12-P12 -> 1.9126418 | S12: =2*PI()-P12-O12-L12-Q12 -> 2.1778745 | T12: =S12+L12-PI() -> 0.032835054 | U12: =d*COS(L12)+½_L4*COS(T12) -> 84.159461 | V12: =d*SIN(L12)+½_L4*SIN(T12) -> 35.634826 | W12: =$L$4-L12 -> 0.12045747 | X12: =RADIANS(90+$B$5)-R12 -> 0.11194011 | Y12: =DEGREES(W12) -> 6.9017046 | Z12: =DEGREES(X12) -> 6.4136961 | AA12: =d*COS(L12) -> 21.727977 | AB12: =d*SIN(L12) -> 33.584148 | AC12: =W+d*COS(R12) -> 146.59095 | AD12: =d*SIN(R12) -> 37.685505 | AE12: =(AA12+AC12)/2 -> 84.159461 | AF12: =(AB12+AD12)/2 -> 35.634826 | AG12: =AE12-AE$4 -> 4.1594612 | AH12: =ABS(AF12-AF$4) -> 0.31693551 | AJ12: {=d*COS(INDEX($L$4:$L$44,AJ10))} -> 34.817157 | AK12: {=d*SIN(INDEX($L$4:$L$44,AJ10))} -> 19.691763
A13: =A12+1 -> 3 | B13: {=IF(F13<40,INDEX($AH$4:$AH$44,F13)+(A13-INDEX($AG$4:$AG47,F13))*(INDEX($AH$4:$AH$44,F13+1)-INDEX($AH$4:$AH$44,F13))/(INDEX($AG$4:$AG47,F13+1)-INDEX($AG$4:$AG47,F13)),"")} -> 0.16513246 | F13: =_xlfn.XMATCH(A13,$AG$4:$AG$44,-1) -> 6 | K13: 10 | L13: =L12-$L$2 -> 0.98149607 | M13: =SQRT(d_2+W_2-2*d*W*COS(L13)) -> 141.72517 | N13: =M13*M13 -> 20086.023 | O13: =ACOS((N13-d_2-L_4_2)/(-2*d*L_4)) -> 1.8629389 | P13: =ACOS((d_2-N13-W_2)/(-2*M13*W)) -> 0.23683949 | Q13: =ACOS((L_4_2-N13-d_2)/(-2*d*M13)) -> 1.0049722 | R13: =PI()-Q13-P13 -> 1.8997809 | S13: =2*PI()-P13-O13-L13-Q13 -> 2.1969386 | T13: =S13+L13-PI() -> 0.036842022 | U13: =d*COS(L13)+½_L4*COS(T13) -> 84.653944 | V13: =d*SIN(L13)+½_L4*SIN(T13) -> 35.554013 | W13: =$L$4-L13 -> 0.13551465 | X13: =RADIANS(90+$B$5)-R13 -> 0.12480099 | Y13: =DEGREES(W13) -> 7.7644177 | Z13: =DEGREES(X13) -> 7.1505701 | AA13: =d*COS(L13) -> 22.231178 | AB13: =d*SIN(L13) -> 33.253191 | AC13: =W+d*COS(R13) -> 147.07671 | AD13: =d*SIN(R13) -> 37.854835 | AE13: =(AA13+AC13)/2 -> 84.653944 | AF13: =(AB13+AD13)/2 -> 35.554013 | AG13: =AE13-AE$4 -> 4.6539436 | AH13: =ABS(AF13-AF$4) -> 0.39774847 | AJ13: {=W+d*COS(INDEX($R$4:$R$44,AJ10))} -> 158.09328 | AK13: {=d*SIN(INDEX($R$4:$R$44,AJ10))} -> 39.954529
A14: =A13+1 -> 4 | B14: {=IF(F14<40,INDEX($AH$4:$AH$44,F14)+(A14-INDEX($AG$4:$AG48,F14))*(INDEX($AH$4:$AH$44,F14+1)-INDEX($AH$4:$AH$44,F14))/(INDEX($AG$4:$AG48,F14+1)-INDEX($AG$4:$AG48,F14)),"")} -> 0.29392541 | F14: =_xlfn.XMATCH(A14,$AG$4:$AG$44,-1) -> 8 | K14: 11 | L14: =L13-$L$2 -> 0.96643888 | M14: =SQRT(d_2+W_2-2*d*W*COS(L14)) -> 141.16165 | N14: =M14*M14 -> 19926.612 | O14: =ACOS((N14-d_2-L_4_2)/(-2*d*L_4)) -> 1.8463239 | P14: =ACOS((d_2-N14-W_2)/(-2*M14*W)) -> 0.23533651 | Q14: =ACOS((L_4_2-N14-d_2)/(-2*d*M14)) -> 1.0190963 | R14: =PI()-Q14-P14 -> 1.8871598 | S14: =2*PI()-P14-O14-L14-Q14 -> 2.2159897 | T14: =S14+L14-PI() -> 0.040835923 | U14: =d*COS(L14)+½_L4*COS(T14) -> 85.142417 | V14: =d*SIN(L14)+½_L4*SIN(T14) -> 35.464809 | W14: =$L$4-L14 -> 0.15057184 | X14: =RADIANS(90+$B$5)-R14 -> 0.13742209 | Y14: =DEGREES(W14) -> 8.6271307 | Z14: =DEGREES(X14) -> 7.8737058 | AA14: =d*COS(L14) -> 22.729338 | AB14: =d*SIN(L14) -> 32.914696 | AC14: =W+d*COS(R14) -> 147.5555 | AD14: =d*SIN(R14) -> 38.014922 | AE14: =(AA14+AC14)/2 -> 85.142417 | AF14: =(AB14+AD14)/2 -> 35.464809 | AG14: =AE14-AE$4 -> 5.1424169 | AH14: =ABS(AF14-AF$4) -> 0.48695293 | AJ14: =W -> 160 | AK14: 0
A15: =A14+1 -> 5 | B15: {=IF(F15<40,INDEX($AH$4:$AH$44,F15)+(A15-INDEX($AG$4:$AG49,F15))*(INDEX($AH$4:$AH$44,F15+1)-INDEX($AH$4:$AH$44,F15))/(INDEX($AG$4:$AG49,F15+1)-INDEX($AG$4:$AG49,F15)),"")} -> 0.46094491 | F15: =_xlfn.XMATCH(A15,$AG$4:$AG$44,-1) -> 10 | K15: 12 | L15: =L14-$L$2 -> 0.9513817 | M15: =SQRT(d_2+W_2-2*d*W*COS(L15)) -> 140.60174 | N15: =M15*M15 -> 19768.849 | O15: =ACOS((N15-d_2-L_4_2)/(-2*d*L_4)) -> 1.8299573 | P15: =ACOS((d_2-N15-W_2)/(-2*M15*W)) -> 0.23376137 | Q15: =ACOS((L_4_2-N15-d_2)/(-2*d*M15)) -> 1.033055 | R15: =PI()-Q15-P15 -> 1.8747763 | S15: =2*PI()-P15-O15-L15-Q15 -> 2.2350299 | T15: =S15+L15-PI() -> 0.04481897 | U15: =d*COS(L15)+½_L4*COS(T15) -> 85.624772 | V15: =d*SIN(L15)+½_L4*SIN(T15) -> 35.367424 | W15: =$L$4-L15 -> 0.16562902 | X15: =RADIANS(90+$B$5)-R15 -> 0.14980567 | Y15: =DEGREES(W15) -> 9.4898438 | Z15: =DEGREES(X15) -> 8.5832324 | AA15: =d*COS(L15) -> 23.222345 | AB15: =d*SIN(L15) -> 32.568738 | AC15: =W+d*COS(R15) -> 148.0272 | AD15: =d*SIN(R15) -> 38.166111 | AE15: =(AA15+AC15)/2 -> 85.624772 | AF15: =(AB15+AD15)/2 -> 35.367424 | AG15: =AE15-AE$4 -> 5.624772 | AH15: =ABS(AF15-AF$4) -> 0.58433758
A16: =A15+1 -> 6 | B16: {=IF(F16<40,INDEX($AH$4:$AH$44,F16)+(A16-INDEX($AG$4:$AG50,F16))*(INDEX($AH$4:$AH$44,F16+1)-INDEX($AH$4:$AH$44,F16))/(INDEX($AG$4:$AG50,F16+1)-INDEX($AG$4:$AG50,F16)),"")} -> 0.66736882 | F16: =_xlfn.XMATCH(A16,$AG$4:$AG$44,-1) -> 12 | K16: 13 | L16: =L15-$L$2 -> 0.93632452 | M16: =SQRT(d_2+W_2-2*d*W*COS(L16)) -> 140.04561 | N16: =M16*M16 -> 19612.772 | O16: =ACOS((N16-d_2-L_4_2)/(-2*d*L_4)) -> 1.8138351 | P16: =ACOS((d_2-N16-W_2)/(-2*M16*W)) -> 0.23211368 | Q16: =ACOS((L_4_2-N16-d_2)/(-2*d*M16)) -> 1.0468506 | R16: =PI()-Q16-P16 -> 1.8626283 | S16: =2*PI()-P16-O16-L16-Q16 -> 2.2540614 | T16: =S16+L16-PI() -> 0.048793274 | U16: =d*COS(L16)+½_L4*COS(T16) -> 86.100899 | V16: =d*SIN(L16)+½_L4*SIN(T16) -> 35.262066 | W16: =$L$4-L16 -> 0.1806862 | X16: =RADIANS(90+$B$5)-R16 -> 0.1619536 | Y16: =DEGREES(W16) -> 10.352557 | Z16: =DEGREES(X16) -> 9.2792575 | AA16: =d*COS(L16) -> 23.710088 | AB16: =d*SIN(L16) -> 32.215396 | AC16: =W+d*COS(R16) -> 148.49171 | AD16: =d*SIN(R16) -> 38.308736 | AE16: =(AA16+AC16)/2 -> 86.100899 | AF16: =(AB16+AD16)/2 -> 35.262066 | AG16: =AE16-AE$4 -> 6.1008989 | AH16: =ABS(AF16-AF$4) -> 0.68969594
A17: =A16+1 -> 7 | B17: {=IF(F17<40,INDEX($AH$4:$AH$44,F17)+(A17-INDEX($AG$4:$AG51,F17))*(INDEX($AH$4:$AH$44,F17+1)-INDEX($AH$4:$AH$44,F17))/(INDEX($AG$4:$AG51,F17+1)-INDEX($AG$4:$AG51,F17)),"")} -> 0.91466507 | F17: =_xlfn.XMATCH(A17,$AG$4:$AG$44,-1) -> 14 | K17: 14 | L17: =L16-$L$2 -> 0.92126733 | M17: =SQRT(d_2+W_2-2*d*W*COS(L17)) -> 139.49342 | N17: =M17*M17 -> 19458.414 | O17: =ACOS((N17-d_2-L_4_2)/(-2*d*L_4)) -> 1.7979537 | P17: =ACOS((d_2-N17-W_2)/(-2*M17*W)) -> 0.23039308 | Q17: =ACOS((L_4_2-N17-d_2)/(-2*d*M17)) -> 1.0604851 | R17: =PI()-Q17-P17 -> 1.8507145 | S17: =2*PI()-P17-O17-L17-Q17 -> 2.2730862 | T17: =S17+L17-PI() -> 0.052760849 | U17: =d*COS(L17)+½_L4*COS(T17) -> 86.570687 | V17: =d*SIN(L17)+½_L4*SIN(T17) -> 35.148936 | W17: =$L$4-L17 -> 0.19574339 | X17: =RADIANS(90+$B$5)-R17 -> 0.17386741 | Y17: =DEGREES(W17) -> 11.21527 | Z17: =DEGREES(X17) -> 9.961869 | AA17: =d*COS(L17) -> 24.192455 | AB17: =d*SIN(L17) -> 31.85475 | AC17: =W+d*COS(R17) -> 148.94892 | AD17: =d*SIN(R17) -> 38.443122 | AE17: =(AA17+AC17)/2 -> 86.570687 | AF17: =(AB17+AD17)/2 -> 35.148936 | AG17: =AE17-AE$4 -> 6.570687 | AH17: =ABS(AF17-AF$4) -> 0.80282584 | AJ17: 21
A18: =A17+1 -> 8 | B18: {=IF(F18<40,INDEX($AH$4:$AH$44,F18)+(A18-INDEX($AG$4:$AG52,F18))*(INDEX($AH$4:$AH$44,F18+1)-INDEX($AH$4:$AH$44,F18))/(INDEX($AG$4:$AG52,F18+1)-INDEX($AG$4:$AG52,F18)),"")} -> 1.2058421 | F18: =_xlfn.XMATCH(A18,$AG$4:$AG$44,-1) -> 17 | K18: 15 | L18: =L17-$L$2 -> 0.90621015 | M18: =SQRT(d_2+W_2-2*d*W*COS(L18)) -> 138.94536 | N18: =M18*M18 -> 19305.812 | O18: =ACOS((N18-d_2-L_4_2)/(-2*d*L_4)) -> 1.78231 | P18: =ACOS((d_2-N18-W_2)/(-2*M18*W)) -> 0.22859924 | Q18: =ACOS((L_4_2-N18-d_2)/(-2*d*M18)) -> 1.0739598 | R18: =PI()-Q18-P18 -> 1.8390336 | S18: =2*PI()-P18-O18-L18-Q18 -> 2.2921061 | T18: =S18+L18-PI() -> 0.056723623 | U18: =d*COS(L18)+½_L4*COS(T18) -> 87.034026 | V18: =d*SIN(L18)+½_L4*SIN(T18) -> 35.028233 | W18: =$L$4-L18 -> 0.21080057 | X18: =RADIANS(90+$B$5)-R18 -> 0.18554833 | Y18: =DEGREES(W18) -> 12.077983 | Z18: =DEGREES(X18) -> 10.631136 | AA18: =d*COS(L18) -> 24.669337 | AB18: =d*SIN(L18) -> 31.486883 | AC18: =W+d*COS(R18) -> 149.39871 | AD18: =d*SIN(R18) -> 38.569583 | AE18: =(AA18+AC18)/2 -> 87.034026 | AF18: =(AB18+AD18)/2 -> 35.028233 | AG18: =AE18-AE$4 -> 7.0340255 | AH18: =ABS(AF18-AF$4) -> 0.92352897 | AJ18: 0 | AK18: 0
A19: =A18+1 -> 9 | B19: {=IF(F19<40,INDEX($AH$4:$AH$44,F19)+(A19-INDEX($AG$4:$AG53,F19))*(INDEX($AH$4:$AH$44,F19+1)-INDEX($AH$4:$AH$44,F19))/(INDEX($AG$4:$AG53,F19+1)-INDEX($AG$4:$AG53,F19)),"")} -> 1.5432541 | F19: =_xlfn.XMATCH(A19,$AG$4:$AG$44,-1) -> 19 | K19: 16 | L19: =L18-$L$2 -> 0.89115297 | M19: =SQRT(d_2+W_2-2*d*W*COS(L19)) -> 138.40159 | N19: =M19*M19 -> 19154.999 | O19: =ACOS((N19-d_2-L_4_2)/(-2*d*L_4)) -> 1.7669012 | P19: =ACOS((d_2-N19-W_2)/(-2*M19*W)) -> 0.22673185 | Q19: =ACOS((L_4_2-N19-d_2)/(-2*d*M19)) -> 1.0872761 | R19: =PI()-Q19-P19 -> 1.8275847 | S19: =2*PI()-P19-O19-L19-Q19 -> 2.3111231 | T19: =S19+L19-PI() -> 0.060683441 | U19: =d*COS(L19)+½_L4*COS(T19) -> 87.490803 | V19: =d*SIN(L19)+½_L4*SIN(T19) -> 34.900151 | W19: =$L$4-L19 -> 0.22585775 | X19: =RADIANS(90+$B$5)-R19 -> 0.19699726 | Y19: =DEGREES(W19) -> 12.940696 | Z19: =DEGREES(X19) -> 11.287111 | AA19: =d*COS(L19) -> 25.140627 | AB19: =d*SIN(L19) -> 31.111877 | AC19: =W+d*COS(R19) -> 149.84098 | AD19: =d*SIN(R19) -> 38.688426 | AE19: =(AA19+AC19)/2 -> 87.490803 | AF19: =(AB19+AD19)/2 -> 34.900151 | AG19: =AE19-AE$4 -> 7.4908029 | AH19: =ABS(AF19-AF$4) -> 1.0516105 | AJ19: {=d*COS(INDEX($L$4:$L$44,AJ17))} -> 27.409487 | AK19: {=d*SIN(INDEX($L$4:$L$44,AJ17))} -> 29.1328
A20: =A19+1 -> 10 | B20: {=IF(F20<40,INDEX($AH$4:$AH$44,F20)+(A20-INDEX($AG$4:$AG54,F20))*(INDEX($AH$4:$AH$44,F20+1)-INDEX($AH$4:$AH$44,F20))/(INDEX($AG$4:$AG54,F20+1)-INDEX($AG$4:$AG54,F20)),"")} -> 1.9290226 | F20: =_xlfn.XMATCH(A20,$AG$4:$AG$44,-1) -> 21 | K20: 17 | L20: =L19-$L$2 -> 0.87609578 | M20: =SQRT(d_2+W_2-2*d*W*COS(L20)) -> 137.86229 | N20: =M20*M20 -> 19006.011 | O20: =ACOS((N20-d_2-L_4_2)/(-2*d*L_4)) -> 1.751725 | P20: =ACOS((d_2-N20-W_2)/(-2*M20*W)) -> 0.22479064 | Q20: =ACOS((L_4_2-N20-d_2)/(-2*d*M20)) -> 1.1004349 | R20: =PI()-Q20-P20 -> 1.8163671 | S20: =2*PI()-P20-O20-L20-Q20 -> 2.3301389 | T20: =S20+L20-PI() -> 0.064642075 | U20: =d*COS(L20)+½_L4*COS(T20) -> 87.940908 | V20: =d*SIN(L20)+½_L4*SIN(T20) -> 34.764883 | W20: =$L$4-L20 -> 0.24091494 | X20: =RADIANS(90+$B$5)-R20 -> 0.20821482 | Y20: =DEGREES(W20) -> 13.803409 | Z20: =DEGREES(X20) -> 11.92983 | AA20: =d*COS(L20) -> 25.606217 | AB20: =d*SIN(L20) -> 30.729817 | AC20: =W+d*COS(R20) -> 150.2756 | AD20: =d*SIN(R20) -> 38.799949 | AE20: =(AA20+AC20)/2 -> 87.940908 | AF20: =(AB20+AD20)/2 -> 34.764883 | AG20: =AE20-AE$4 -> 7.9409077 | AH20: =ABS(AF20-AF$4) -> 1.1868788 | AJ20: {=W+d*COS(INDEX($R$4:$R$44,AJ17))} -> 151.93525 | AK20: {=d*SIN(INDEX($R$4:$R$44,AJ17))} -> 39.178562
A21: =A20+1 -> 11 | B21: {=IF(F21<40,INDEX($AH$4:$AH$44,F21)+(A21-INDEX($AG$4:$AG55,F21))*(INDEX($AH$4:$AH$44,F21+1)-INDEX($AH$4:$AH$44,F21))/(INDEX($AG$4:$AG55,F21+1)-INDEX($AG$4:$AG55,F21)),"")} -> 2.368999 | F21: =_xlfn.XMATCH(A21,$AG$4:$AG$44,-1) -> 24 | K21: 18 | L21: =L20-$L$2 -> 0.8610386 | M21: =SQRT(d_2+W_2-2*d*W*COS(L21)) -> 137.32764 | N21: =M21*M21 -> 18858.88 | O21: =ACOS((N21-d_2-L_4_2)/(-2*d*L_4)) -> 1.7367793 | P21: =ACOS((d_2-N21-W_2)/(-2*M21*W)) -> 0.22277537 | Q21: =ACOS((L_4_2-N21-d_2)/(-2*d*M21)) -> 1.1134367 | R21: =PI()-Q21-P21 -> 1.8053805 | S21: =2*PI()-P21-O21-L21-Q21 -> 2.3491553 | T21: =S21+L21-PI() -> 0.068601226 | U21: =d*COS(L21)+½_L4*COS(T21) -> 88.384228 | V21: =d*SIN(L21)+½_L4*SIN(T21) -> 34.622617 | W21: =$L$4-L21 -> 0.25597212 | X21: =RADIANS(90+$B$5)-R21 -> 0.21920138 | Y21: =DEGREES(W21) -> 14.666122 | Z21: =DEGREES(X21) -> 12.559314 | AA21: =d*COS(L21) -> 26.066001 | AB21: =d*SIN(L21) -> 30.340791 | AC21: =W+d*COS(R21) -> 150.70246 | AD21: =d*SIN(R21) -> 38.904443 | AE21: =(AA21+AC21)/2 -> 88.384228 | AF21: =(AB21+AD21)/2 -> 34.622617 | AG21: =AE21-AE$4 -> 8.3842281 | AH21: =ABS(AF21-AF$4) -> 1.329145 | AJ21: =W -> 160 | AK21: 0
A22: =A21+1 -> 12 | B22: {=IF(F22<40,INDEX($AH$4:$AH$44,F22)+(A22-INDEX($AG$4:$AG56,F22))*(INDEX($AH$4:$AH$44,F22+1)-INDEX($AH$4:$AH$44,F22))/(INDEX($AG$4:$AG56,F22+1)-INDEX($AG$4:$AG56,F22)),"")} -> 2.8680862 | F22: =_xlfn.XMATCH(A22,$AG$4:$AG$44,-1) -> 26 | K22: 19 | L22: =L21-$L$2 -> 0.84598142 | M22: =SQRT(d_2+W_2-2*d*W*COS(L22)) -> 136.79781 | N22: =M22*M22 -> 18713.64 | O22: =ACOS((N22-d_2-L_4_2)/(-2*d*L_4)) -> 1.7220623 | P22: =ACOS((d_2-N22-W_2)/(-2*M22*W)) -> 0.22068583 | Q22: =ACOS((L_4_2-N22-d_2)/(-2*d*M22)) -> 1.126282 | R22: =PI()-Q22-P22 -> 1.7946249 | S22: =2*PI()-P22-O22-L22-Q22 -> 2.3681738 | T22: =S22+L22-PI() -> 0.07256253 | U22: =d*COS(L22)+½_L4*COS(T22) -> 88.820652 | V22: =d*SIN(L22)+½_L4*SIN(T22) -> 34.473539 | W22: =$L$4-L22 -> 0.27102931 | X22: =RADIANS(90+$B$5)-R22 -> 0.22995707 | Y22: =DEGREES(W22) -> 15.528835 | Z22: =DEGREES(X22) -> 13.17557 | AA22: =d*COS(L22) -> 26.519876 | AB22: =d*SIN(L22) -> 29.944886 | AC22: =W+d*COS(R22) -> 151.12143 | AD22: =d*SIN(R22) -> 39.002192 | AE22: =(AA22+AC22)/2 -> 88.820652 | AF22: =(AB22+AD22)/2 -> 34.473539 | AG22: =AE22-AE$4 -> 8.8206524 | AH22: =ABS(AF22-AF$4) -> 1.4782229
A23: =A22+1 -> 13 | B23: {=IF(F23<40,INDEX($AH$4:$AH$44,F23)+(A23-INDEX($AG$4:$AG57,F23))*(INDEX($AH$4:$AH$44,F23+1)-INDEX($AH$4:$AH$44,F23))/(INDEX($AG$4:$AG57,F23+1)-INDEX($AG$4:$AG57,F23)),"")} -> 3.4357099 | F23: =_xlfn.XMATCH(A23,$AG$4:$AG$44,-1) -> 29 | K23: 20 | L23: =L22-$L$2 -> 0.83092423 | M23: =SQRT(d_2+W_2-2*d*W*COS(L23)) -> 136.27298 | N23: =M23*M23 -> 18570.324 | O23: =ACOS((N23-d_2-L_4_2)/(-2*d*L_4)) -> 1.7075726 | P23: =ACOS((d_2-N23-W_2)/(-2*M23*W)) -> 0.21852186 | Q23: =ACOS((L_4_2-N23-d_2)/(-2*d*M23)) -> 1.1389706 | R23: =PI()-Q23-P23 -> 1.7841002 | S23: =2*PI()-P23-O23-L23-Q23 -> 2.387196 | T23: =S23+L23-PI() -> 0.076527561 | U23: =d*COS(L23)+½_L4*COS(T23) -> 89.250069 | V23: =d*SIN(L23)+½_L4*SIN(T23) -> 34.317833 | W23: =$L$4-L23 -> 0.28608649 | X23: =RADIANS(90+$B$5)-R23 -> 0.24048177 | Y23: =DEGREES(W23) -> 16.391548 | Z23: =DEGREES(X23) -> 13.778591 | AA23: =d*COS(L23) -> 26.967738 | AB23: =d*SIN(L23) -> 29.542192 | AC23: =W+d*COS(R23) -> 151.5324 | AD23: =d*SIN(R23) -> 39.093474 | AE23: =(AA23+AC23)/2 -> 89.250069 | AF23: =(AB23+AD23)/2 -> 34.317833 | AG23: =AE23-AE$4 -> 9.2500689 | AH23: =ABS(AF23-AF$4) -> 1.6339287
A24: =A23+1 -> 14 | B24: {=IF(F24<40,INDEX($AH$4:$AH$44,F24)+(A24-INDEX($AG$4:$AG58,F24))*(INDEX($AH$4:$AH$44,F24+1)-INDEX($AH$4:$AH$44,F24))/(INDEX($AG$4:$AG58,F24+1)-INDEX($AG$4:$AG58,F24)),"")} -> 4.0816392 | F24: =_xlfn.XMATCH(A24,$AG$4:$AG$44,-1) -> 32 | K24: 21 | L24: =L23-$L$2 -> 0.81586705 | M24: =SQRT(d_2+W_2-2*d*W*COS(L24)) -> 135.75332 | N24: =M24*M24 -> 18428.964 | O24: =ACOS((N24-d_2-L_4_2)/(-2*d*L_4)) -> 1.6933089 | P24: =ACOS((d_2-N24-W_2)/(-2*M24*W)) -> 0.21628331 | Q24: =ACOS((L_4_2-N24-d_2)/(-2*d*M24)) -> 1.1515026 | R24: =PI()-Q24-P24 -> 1.7738068 | S24: =2*PI()-P24-O24-L24-Q24 -> 2.4062234 | T24: =S24+L24-PI() -> 0.080497835 | U24: =d*COS(L24)+½_L4*COS(T24) -> 89.672366 | V24: =d*SIN(L24)+½_L4*SIN(T24) -> 34.155681 | W24: =$L$4-L24 -> 0.30114367 | X24: =RADIANS(90+$B$5)-R24 -> 0.25077515 | Y24: =DEGREES(W24) -> 17.254261 | Z24: =DEGREES(X24) -> 14.368358 | AA24: =d*COS(L24) -> 27.409487 | AB24: =d*SIN(L24) -> 29.1328 | AC24: =W+d*COS(R24) -> 151.93525 | AD24: =d*SIN(R24) -> 39.178562 | AE24: =(AA24+AC24)/2 -> 89.672366 | AF24: =(AB24+AD24)/2 -> 34.155681 | AG24: =AE24-AE$4 -> 9.6723659 | AH24: =ABS(AF24-AF$4) -> 1.7960807
A25: =A24+1 -> 15 | B25: {=IF(F25<40,INDEX($AH$4:$AH$44,F25)+(A25-INDEX($AG$4:$AG59,F25))*(INDEX($AH$4:$AH$44,F25+1)-INDEX($AH$4:$AH$44,F25))/(INDEX($AG$4:$AG59,F25+1)-INDEX($AG$4:$AG59,F25)),"")} -> 4.8226053 | F25: =_xlfn.XMATCH(A25,$AG$4:$AG$44,-1) -> 35 | K25: 22 | L25: =L24-$L$2 -> 0.80080986 | M25: =SQRT(d_2+W_2-2*d*W*COS(L25)) -> 135.23902 | N25: =M25*M25 -> 18289.593 | O25: =ACOS((N25-d_2-L_4_2)/(-2*d*L_4)) -> 1.6792704 | P25: =ACOS((d_2-N25-W_2)/(-2*M25*W)) -> 0.21397008 | Q25: =ACOS((L_4_2-N25-d_2)/(-2*d*M25)) -> 1.1638773 | R25: =PI()-Q25-P25 -> 1.7637452 | S25: =2*PI()-P25-O25-L25-Q25 -> 2.4252576 | T25: =S25+L25-PI() -> 0.084474816 | U25: =d*COS(L25)+½_L4*COS(T25) -> 90.087432 | V25: =d*SIN(L25)+½_L4*SIN(T25) -> 33.987263 | W25: =$L$4-L25 -> 0.31620086 | X25: =RADIANS(90+$B$5)-R25 -> 0.26083668 | Y25: =DEGREES(W25) -> 18.116975 | Z25: =DEGREES(X25) -> 14.944841 | AA25: =d*COS(L25) -> 27.845021 | AB25: =d*SIN(L25) -> 28.716804 | AC25: =W+d*COS(R25) -> 152.32984 | AD25: =d*SIN(R25) -> 39.257721 | AE25: =(AA25+AC25)/2 -> 90.087432 | AF25: =(AB25+AD25)/2 -> 33.987263 | AG25: =AE25-AE$4 -> 10.087432 | AH25: =ABS(AF25-AF$4) -> 1.9644993
A26: =A25+1 -> 16 | B26: {=IF(F26<40,INDEX($AH$4:$AH$44,F26)+(A26-INDEX($AG$4:$AG60,F26))*(INDEX($AH$4:$AH$44,F26+1)-INDEX($AH$4:$AH$44,F26))/(INDEX($AG$4:$AG60,F26+1)-INDEX($AG$4:$AG60,F26)),"")} -> 5.6854674 | F26: =_xlfn.XMATCH(A26,$AG$4:$AG$44,-1) -> 39 | K26: 23 | L26: =L25-$L$2 -> 0.78575268 | M26: =SQRT(d_2+W_2-2*d*W*COS(L26)) -> 134.73026 | N26: =M26*M26 -> 18152.242 | O26: =ACOS((N26-d_2-L_4_2)/(-2*d*L_4)) -> 1.6654564 | P26: =ACOS((d_2-N26-W_2)/(-2*M26*W)) -> 0.21158211 | Q26: =ACOS((L_4_2-N26-d_2)/(-2*d*M26)) -> 1.1760942 | R26: =PI()-Q26-P26 -> 1.7539163 | S26: =2*PI()-P26-O26-L26-Q26 -> 2.4442999 | T26: =S26+L26-PI() -> 0.088459913 | U26: =d*COS(L26)+½_L4*COS(T26) -> 90.495156 | V26: =d*SIN(L26)+½_L4*SIN(T26) -> 33.812755 | W26: =$L$4-L26 -> 0.33125804 | X26: =RADIANS(90+$B$5)-R26 -> 0.27066563 | Y26: =DEGREES(W26) -> 18.979688 | Z26: =DEGREES(X26) -> 15.507998 | AA26: =d*COS(L26) -> 28.274242 | AB26: =d*SIN(L26) -> 28.294297 | AC26: =W+d*COS(R26) -> 152.71607 | AD26: =d*SIN(R26) -> 39.331214 | AE26: =(AA26+AC26)/2 -> 90.495156 | AF26: =(AB26+AD26)/2 -> 33.812755 | AG26: =AE26-AE$4 -> 10.495156 | AH26: =ABS(AF26-AF$4) -> 2.1390067
A27: =A26+1 -> 17 | B27: {=IF(F27<40,INDEX($AH$4:$AH$44,F27)+(A27-INDEX($AG$4:$AG61,F27))*(INDEX($AH$4:$AH$44,F27+1)-INDEX($AH$4:$AH$44,F27))/(INDEX($AG$4:$AG61,F27+1)-INDEX($AG$4:$AG61,F27)),"")} | F27: =_xlfn.XMATCH(A27,$AG$4:$AG$44,-1) -> 41 | K27: 24 | L27: =L26-$L$2 -> 0.7706955 | M27: =SQRT(d_2+W_2-2*d*W*COS(L27)) -> 134.22721 | N27: =M27*M27 -> 18016.943 | O27: =ACOS((N27-d_2-L_4_2)/(-2*d*L_4)) -> 1.6518663 | P27: =ACOS((d_2-N27-W_2)/(-2*M27*W)) -> 0.2091194 | Q27: =ACOS((L_4_2-N27-d_2)/(-2*d*M27)) -> 1.1881524 | R27: =PI()-Q27-P27 -> 1.7443208 | S27: =2*PI()-P27-O27-L27-Q27 -> 2.4633516 | T27: =S27+L27-PI() -> 0.092454487 | U27: =d*COS(L27)+½_L4*COS(T27) -> 90.895427 | V27: =d*SIN(L27)+½_L4*SIN(T27) -> 33.632335 | W27: =$L$4-L27 -> 0.34631522 | X27: =RADIANS(90+$B$5)-R27 -> 0.2802611 | Y27: =DEGREES(W27) -> 19.842401 | Z27: =DEGREES(X27) -> 16.057778 | AA27: =d*COS(L27) -> 28.697053 | AB27: =d*SIN(L27) -> 27.865375 | AC27: =W+d*COS(R27) -> 153.0938 | AD27: =d*SIN(R27) -> 39.399294 | AE27: =(AA27+AC27)/2 -> 90.895427 | AF27: =(AB27+AD27)/2 -> 33.632335 | AG27: =AE27-AE$4 -> 10.895427 | AH27: =ABS(AF27-AF$4) -> 2.3194271
A28: =A27+1 -> 18 | B28: {=IF(F28<40,INDEX($AH$4:$AH$44,F28)+(A28-INDEX($AG$4:$AG62,F28))*(INDEX($AH$4:$AH$44,F28+1)-INDEX($AH$4:$AH$44,F28))/(INDEX($AG$4:$AG62,F28+1)-INDEX($AG$4:$AG62,F28)),"")} | F28: =_xlfn.XMATCH(A28,$AG$4:$AG$44,-1) -> 41 | K28: 25 | L28: =L27-$L$2 -> 0.75563831 | M28: =SQRT(d_2+W_2-2*d*W*COS(L28)) -> 133.73005 | N28: =M28*M28 -> 17883.725 | O28: =ACOS((N28-d_2-L_4_2)/(-2*d*L_4)) -> 1.6385001 | P28: =ACOS((d_2-N28-W_2)/(-2*M28*W)) -> 0.20658195 | Q28: =ACOS((L_4_2-N28-d_2)/(-2*d*M28)) -> 1.2000508 | R28: =PI()-Q28-P28 -> 1.7349599 | S28: =2*PI()-P28-O28-L28-Q28 -> 2.4824142 | T28: =S28+L28-PI() -> 0.09645985 | U28: =d*COS(L28)+½_L4*COS(T28) -> 91.288134 | V28: =d*SIN(L28)+½_L4*SIN(T28) -> 33.446176 | W28: =$L$4-L28 -> 0.36137241 | X28: =RADIANS(90+$B$5)-R28 -> 0.28962199 | Y28: =DEGREES(W28) -> 20.705114 | Z28: =DEGREES(X28) -> 16.594118 | AA28: =d*COS(L28) -> 29.113359 | AB28: =d*SIN(L28) -> 27.430136 | AC28: =W+d*COS(R28) -> 153.46291 | AD28: =d*SIN(R28) -> 39.462216 | AE28: =(AA28+AC28)/2 -> 91.288134 | AF28: =(AB28+AD28)/2 -> 33.446176 | AG28: =AE28-AE$4 -> 11.288134 | AH28: =ABS(AF28-AF$4) -> 2.5055862
A29: =A28+1 -> 19 | B29: {=IF(F29<40,INDEX($AH$4:$AH$44,F29)+(A29-INDEX($AG$4:$AG63,F29))*(INDEX($AH$4:$AH$44,F29+1)-INDEX($AH$4:$AH$44,F29))/(INDEX($AG$4:$AG63,F29+1)-INDEX($AG$4:$AG63,F29)),"")} | F29: =_xlfn.XMATCH(A29,$AG$4:$AG$44,-1) -> 41 | K29: 26 | L29: =L28-$L$2 -> 0.74058113 | M29: =SQRT(d_2+W_2-2*d*W*COS(L29)) -> 133.23896 | N29: =M29*M29 -> 17752.62 | O29: =ACOS((N29-d_2-L_4_2)/(-2*d*L_4)) -> 1.6253576 | P29: =ACOS((d_2-N29-W_2)/(-2*M29*W)) -> 0.20396984 | Q29: =ACOS((L_4_2-N29-d_2)/(-2*d*M29)) -> 1.211788 | R29: =PI()-Q29-P29 -> 1.7258348 | S29: =2*PI()-P29-O29-L29-Q29 -> 2.5014888 | T29: =S29+L29-PI() -> 0.10047727 | U29: =d*COS(L29)+½_L4*COS(T29) -> 91.673169 | V29: =d*SIN(L29)+½_L4*SIN(T29) -> 33.254451 | W29: =$L$4-L29 -> 0.37642959 | X29: =RADIANS(90+$B$5)-R29 -> 0.29874709 | Y29: =DEGREES(W29) -> 21.567827 | Z29: =DEGREES(X29) -> 17.116947 | AA29: =d*COS(L29) -> 29.523063 | AB29: =d*SIN(L29) -> 26.988678 | AC29: =W+d*COS(R29) -> 153.82327 | AD29: =d*SIN(R29) -> 39.520223 | AE29: =(AA29+AC29)/2 -> 91.673169 | AF29: =(AB29+AD29)/2 -> 33.254451 | AG29: =AE29-AE$4 -> 11.673169 | AH29: =ABS(AF29-AF$4) -> 2.6973113
A30: =A29+1 -> 20 | B30: {=IF(F30<40,INDEX($AH$4:$AH$44,F30)+(A30-INDEX($AG$4:$AG64,F30))*(INDEX($AH$4:$AH$44,F30+1)-INDEX($AH$4:$AH$44,F30))/(INDEX($AG$4:$AG64,F30+1)-INDEX($AG$4:$AG64,F30)),"")} | F30: =_xlfn.XMATCH(A30,$AG$4:$AG$44,-1) -> 41 | K30: 27 | L30: =L29-$L$2 -> 0.72552395 | M30: =SQRT(d_2+W_2-2*d*W*COS(L30)) -> 132.75412 | N30: =M30*M30 -> 17623.656 | O30: =ACOS((N30-d_2-L_4_2)/(-2*d*L_4)) -> 1.612439 | P30: =ACOS((d_2-N30-W_2)/(-2*M30*W)) -> 0.20128317 | Q30: =ACOS((L_4_2-N30-d_2)/(-2*d*M30)) -> 1.2233625 | R30: =PI()-Q30-P30 -> 1.7169469 | S30: =2*PI()-P30-O30-L30-Q30 -> 2.5205767 | T30: =S30+L30-PI() -> 0.10450797 | U30: =d*COS(L30)+½_L4*COS(T30) -> 92.05042 | V30: =d*SIN(L30)+½_L4*SIN(T30) -> 33.05733 | W30: =$L$4-L30 -> 0.39148677 | X30: =RADIANS(90+$B$5)-R30 -> 0.30763498 | Y30: =DEGREES(W30) -> 22.43054 | Z30: =DEGREES(X30) -> 17.626186 | AA30: =d*COS(L30) -> 29.926075 | AB30: =d*SIN(L30) -> 26.541101 | AC30: =W+d*COS(R30) -> 154.17476 | AD30: =d*SIN(R30) -> 39.57356 | AE30: =(AA30+AC30)/2 -> 92.05042 | AF30: =(AB30+AD30)/2 -> 33.05733 | AG30: =AE30-AE$4 -> 12.05042 | AH30: =ABS(AF30-AF$4) -> 2.8944315
A31: =A30+1 -> 21 | B31: {=IF(F31<40,INDEX($AH$4:$AH$44,F31)+(A31-INDEX($AG$4:$AG65,F31))*(INDEX($AH$4:$AH$44,F31+1)-INDEX($AH$4:$AH$44,F31))/(INDEX($AG$4:$AG65,F31+1)-INDEX($AG$4:$AG65,F31)),"")} | F31: =_xlfn.XMATCH(A31,$AG$4:$AG$44,-1) -> 41 | K31: 28 | L31: =L30-$L$2 -> 0.71046676 | M31: =SQRT(d_2+W_2-2*d*W*COS(L31)) -> 132.27571 | N31: =M31*M31 -> 17496.863 | O31: =ACOS((N31-d_2-L_4_2)/(-2*d*L_4)) -> 1.5997447 | P31: =ACOS((d_2-N31-W_2)/(-2*M31*W)) -> 0.19852212 | Q31: =ACOS((L_4_2-N31-d_2)/(-2*d*M31)) -> 1.2347728 | R31: =PI()-Q31-P31 -> 1.7082978 | S31: =2*PI()-P31-O31-L31-Q31 -> 2.539679 | T31: =S31+L31-PI() -> 0.10855312 | U31: =d*COS(L31)+½_L4*COS(T31) -> 92.419779 | V31: =d*SIN(L31)+½_L4*SIN(T31) -> 32.854985 | W31: =$L$4-L31 -> 0.40654396 | X31: =RADIANS(90+$B$5)-R31 -> 0.31628416 | Y31: =DEGREES(W31) -> 23.293253 | Z31: =DEGREES(X31) -> 18.121747 | AA31: =d*COS(L31) -> 30.322302 | AB31: =d*SIN(L31) -> 26.087507 | AC31: =W+d*COS(R31) -> 154.51726 | AD31: =d*SIN(R31) -> 39.622462 | AE31: =(AA31+AC31)/2 -> 92.419779 | AF31: =(AB31+AD31)/2 -> 32.854985 | AG31: =AE31-AE$4 -> 12.419779 | AH31: =ABS(AF31-AF$4) -> 3.0967771
A32: =A31+1 -> 22 | B32: {=IF(F32<40,INDEX($AH$4:$AH$44,F32)+(A32-INDEX($AG$4:$AG66,F32))*(INDEX($AH$4:$AH$44,F32+1)-INDEX($AH$4:$AH$44,F32))/(INDEX($AG$4:$AG66,F32+1)-INDEX($AG$4:$AG66,F32)),"")} | F32: =_xlfn.XMATCH(A32,$AG$4:$AG$44,-1) -> 41 | K32: 29 | L32: =L31-$L$2 -> 0.69540958 | M32: =SQRT(d_2+W_2-2*d*W*COS(L32)) -> 131.80391 | N32: =M32*M32 -> 17372.271 | O32: =ACOS((N32-d_2-L_4_2)/(-2*d*L_4)) -> 1.5872751 | P32: =ACOS((d_2-N32-W_2)/(-2*M32*W)) -> 0.19568688 | Q32: =ACOS((L_4_2-N32-d_2)/(-2*d*M32)) -> 1.2460168 | R32: =PI()-Q32-P32 -> 1.699889 | S32: =2*PI()-P32-O32-L32-Q32 -> 2.5587969 | T32: =S32+L32-PI() -> 0.11261385 | U32: =d*COS(L32)+½_L4*COS(T32) -> 92.781139 | V32: =d*SIN(L32)+½_L4*SIN(T32) -> 32.647581 | W32: =$L$4-L32 -> 0.42160114 | X32: =RADIANS(90+$B$5)-R32 -> 0.32469294 | Y32: =DEGREES(W32) -> 24.155966 | Z32: =DEGREES(X32) -> 18.603535 | AA32: =d*COS(L32) -> 30.711654 | AB32: =d*SIN(L32) -> 25.627999 | AC32: =W+d*COS(R32) -> 154.85062 | AD32: =d*SIN(R32) -> 39.667164 | AE32: =(AA32+AC32)/2 -> 92.781139 | AF32: =(AB32+AD32)/2 -> 32.647581 | AG32: =AE32-AE$4 -> 12.781139 | AH32: =ABS(AF32-AF$4) -> 3.3041804
A33: =A32+1 -> 23 | B33: {=IF(F33<40,INDEX($AH$4:$AH$44,F33)+(A33-INDEX($AG$4:$AG67,F33))*(INDEX($AH$4:$AH$44,F33+1)-INDEX($AH$4:$AH$44,F33))/(INDEX($AG$4:$AG67,F33+1)-INDEX($AG$4:$AG67,F33)),"")} | F33: =_xlfn.XMATCH(A33,$AG$4:$AG$44,-1) -> 41 | K33: 30 | L33: =L32-$L$2 -> 0.6803524 | M33: =SQRT(d_2+W_2-2*d*W*COS(L33)) -> 131.3389 | N33: =M33*M33 -> 17249.906 | O33: =ACOS((N33-d_2-L_4_2)/(-2*d*L_4)) -> 1.5750311 | P33: =ACOS((d_2-N33-W_2)/(-2*M33*W)) -> 0.19277772 | Q33: =ACOS((L_4_2-N33-d_2)/(-2*d*M33)) -> 1.2570925 | R33: =PI()-Q33-P33 -> 1.6917224 | S33: =2*PI()-P33-O33-L33-Q33 -> 2.5779315 | T33: =S33+L33-PI() -> 0.11669127 | U33: =d*COS(L33)+½_L4*COS(T33) -> 93.134391 | V33: =d*SIN(L33)+½_L4*SIN(T33) -> 32.435287 | W33: =$L$4-L33 -> 0.43665833 | X33: =RADIANS(90+$B$5)-R33 -> 0.33285954 | Y33: =DEGREES(W33) -> 25.018679 | Z33: =DEGREES(X33) -> 19.071447 | AA33: =d*COS(L33) -> 31.094043 | AB33: =d*SIN(L33) -> 25.16268 | AC33: =W+d*COS(R33) -> 155.17474 | AD33: =d*SIN(R33) -> 39.707894 | AE33: =(AA33+AC33)/2 -> 93.134391 | AF33: =(AB33+AD33)/2 -> 32.435287 | AG33: =AE33-AE$4 -> 13.134391 | AH33: =ABS(AF33-AF$4) -> 3.5164749
... A44: =A43+1 -> 34 | B44: {=IF(F44<40,INDEX($AH$4:$AH$44,F44)+(A44-INDEX($AG$4:$AG78,F44))*(INDEX($AH$4:$AH$44,F44+1)-INDEX($AH$4:$AH$44,F44))/(INDEX($AG$4:$AG78,F44+1)-INDEX($AG$4:$AG78,F44)),"")} | F44: =_xlfn.XMATCH(A44,$AG$4:$AG$44,-1) -> 41 | K44: 41 | L44: =L43-$L$2 -> 0.51472338 | M44: =SQRT(d_2+W_2-2*d*W*COS(L44)) -> 126.72217 | N44: =M44*M44 -> 16058.51 | O44: =ACOS((N44-d_2-L_4_2)/(-2*d*L_4)) -> 1.4555702 | P44: =ACOS((d_2-N44-W_2)/(-2*M44*W)) -> 0.15602547 | Q44: =ACOS((L_4_2-N44-d_2)/(-2*d*M44)) -> 1.3670848 | R44: =PI()-Q44-P44 -> 1.6184824 | S44: =2*PI()-P44-O44-L44-Q44 -> 2.7897815 | T44: =S44+L44-PI() -> 0.16291223 | U44: =d*COS(L44)+½_L4*COS(T44) -> 96.455218 | V44: =d*SIN(L44)+½_L4*SIN(T44) -> 29.823146 | W44: =$L$4-L44 -> 0.60228735 | X44: =RADIANS(90+$B$5)-R44 -> 0.40609952 | Y44: =DEGREES(W44) -> 34.508523 | Z44: =DEGREES(X44) -> 23.267789 | AA44: =d*COS(L44) -> 34.817157 | AB44: =d*SIN(L44) -> 19.691763 | AC44: =W+d*COS(R44) -> 158.09328 | AD44: =d*SIN(R44) -> 39.954529 | AE44: =(AA44+AC44)/2 -> 96.455218 | AF44: =(AB44+AD44)/2 -> 29.823146 | AG44: =AE44-AE$4 -> 16.455218 | AH44: =ABS(AF44-AF$4) -> 6.1286155
A45: =A44+1 -> 35 | B45: {=IF(F45<40,INDEX($AH$4:$AH$44,F45)+(A45-INDEX($AG$4:$AG79,F45))*(INDEX($AH$4:$AH$44,F45+1)-INDEX($AH$4:$AH$44,F45))/(INDEX($AG$4:$AG79,F45+1)-INDEX($AG$4:$AG79,F45)),"")} | F45: =_xlfn.XMATCH(A45,$AG$4:$AG$44,-1) -> 41
A46: =A45+1 -> 36 | B46: {=IF(F46<40,INDEX($AH$4:$AH$44,F46)+(A46-INDEX($AG$4:$AG80,F46))*(INDEX($AH$4:$AH$44,F46+1)-INDEX($AH$4:$AH$44,F46))/(INDEX($AG$4:$AG80,F46+1)-INDEX($AG$4:$AG80,F46)),"")} | F46: =_xlfn.XMATCH(A46,$AG$4:$AG$44,-1) -> 41
A47: =A46+1 -> 37 | B47: {=IF(F47<40,INDEX($AH$4:$AH$44,F47)+(A47-INDEX($AG$4:$AG81,F47))*(INDEX($AH$4:$AH$44,F47+1)-INDEX($AH$4:$AH$44,F47))/(INDEX($AG$4:$AG81,F47+1)-INDEX($AG$4:$AG81,F47)),"")} | F47: =_xlfn.XMATCH(A47,$AG$4:$AG$44,-1) -> 41

Sheet Input Parameters
A1: W | B1: 160 | C1: mm
A2: L | B2: 220 | C2: mm
A3: Rmin | B3: 400 | C3: mm
A4: W/d | B4: 4 | C4: mm
A5: d | B5: 40 | C5: mm | D5: * if blank W/d controls value of d
A6: β | B6: 26 | C6: °
